<?xml version="1.0" ?>
<!-- 
 This is a standalone URDF model of 2WD smart car robot 
 -->

<robot name="mobile_robot"
	xmlns:xacro="http://ros.org/wiki/xacro">
	<xacro:include filename="$(find mobile_robot_description)/urdf/mobile_robot_gazebo.xacro"/>

	<xacro:property name="M_PI" value="3.1415926535897931" />
	<xacro:property name="M_PI_2" value="1.570796327" />
	<xacro:property name="DEG_TO_RAD" value="0.017453293" />

	<!-- <xacro:macro name="mobile_robot">   -->

	<link name="base_footprint"/>
	<!--
       Base link is set at the bottom of the base mould.
       This is done to be compatible with the way base link
       was configured for turtlebot 1. Refer to
       
       https://github.com/turtlebot/turtlebot/issues/40
       
       To put the base link at the more oft used wheel
       axis, set the z-distance from the base_footprint
       to 0.352.
      -->
	<joint name="base_joint" type="fixed">
		<origin xyz="0 0 0.05" rpy="0 0 0" />
		<parent link="base_footprint"/>
		<child link="base_link" />
		<dynamics damping="0"/>
	</joint>

	<link name="base_link">
		<visual>
			<geometry>
				<!-- new mesh -->
				<mesh filename="package://mobile_robot_description/meshes/stl/basenew.STL" scale="0.001 0.001 0.001"/>
			</geometry>
			<origin xyz="0 0 0" rpy="0 0 1.57"/>
		</visual>
		
		<collision>
			<origin xyz="0 0 0" rpy="0 0 0"/>
			<geometry>
			 <box size="0.14 0.14 0.07"/>
			</geometry>
		</collision>

		<inertial>
			<!-- COM experimentally determined -->
			<origin xyz="0 -0.0055 -0.0090"/>
			<mass value="1"/>
			<!-- 2.4/2.6 kg for small/big battery pack -->

			<inertia ixx = "0.0012"	ixy = "0.0000"	ixz = "0.0000"
			iyx = "0.0000"	iyy = "0.0037"	iyz = "0.0001"
			izx = "0.0000"	izy = "0.0001"	izz = "0.0039" />
		</inertial>
	</link>

	<!-- Wheel and caster wheel link  -->


	<!-- NOTE This may prevent gazebo from working with this model -->
	<joint name="left_wheel_joint" type="continuous">
		<origin xyz="0 0.046 -0.0121" rpy="0 0 0"/>
		<parent link="base_link"/>
		<child link="left_wheel_link"/>
		<axis xyz="0 1 0"/>
		<dynamics damping="1"/>
		<limit effort="100" velocity="100"/>
		<joint_properties damping="1" friction="100.0"/>
		
	</joint>



	<link name="left_wheel_link">
		<inertial>
			<origin xyz="0 -0.0175 0"/>
			<mass value="0.3701" />
			<inertia ixx = "0.0003"	ixy = "0.0000"	ixz = "0.0000"
			iyx = "0.0000"	iyy = "0.0003"	iyz = "0.0000"
			izx = "0.0000"	izy = "0.0000"	izz = "0.0003" />
		</inertial>	

		<visual>
			<origin xyz="0 0 0" rpy="0 0 3.14" />
			<geometry>
				<!-- new mesh -->
				<mesh filename="package://mobile_robot_description/meshes/stl/tire.STL" scale="0.001 0.001 0.001"/>

			</geometry>
		</visual>

		<collision>
			<origin xyz="0 0 0" rpy="0 0 0" />
			<geometry>
				<sphere radius="0.033"/>
			</geometry>
		</collision>
	</link>




	<link name="right_wheel_link">
		<inertial>
			<origin xyz="0 -0.0175 0"/>
			<mass value="0.3701" />
			<inertia ixx = "0.0003"	ixy = "0.0000"	ixz = "0.0000"
			iyx = "0.0000"	iyy = "0.0003"	iyz = "0.0000"
			izx = "0.0000"	izy = "0.0000"	izz = "0.0003" />
		</inertial>

		<visual>
			<origin xyz="0 0 0" rpy="0 0 0" />
			<geometry>
				<!-- new mesh -->
				<mesh filename="package://mobile_robot_description/meshes/stl/tire.STL" scale="0.001 0.001 0.001"/>

			</geometry>

		</visual>

		<collision>
			<origin xyz="0 0 0" rpy="0 0 0" />
			<geometry>
				<sphere radius="0.033"/>
			</geometry>
		</collision>
	</link>

	<!-- Fixed because we never rotate it anyway, it is just for show -->
	<!-- NOTE This may prevent gazebo from working with this model -->
	<joint name="right_wheel_joint" type="continuous">
		<origin xyz="0 -0.046 -0.0121" rpy="0 0 0"/>
		<parent link="base_link"/>
		<child link="right_wheel_link"/>
		<axis xyz="0 1 0"/>
		<dynamics damping="1"/>
		<limit effort="100" velocity="100"/>
		<joint_properties damping="1" friction="100.0"/>
	</joint>


	<!--   
    <joint name="caster_front_joint" type="fixed">
      <parent link="base_link"/>
      <child link="chefbot_caster_front_link"/>
      <origin xyz="0.115 0.0 0.007" rpy="${-M_PI/2} 0 0"/>
    </joint>


    <link name="chefbot_caster_front_link">
      <collision>
        <geometry>
          <cylinder length="0.0176" radius="0.017"/>
        </geometry>
        <origin rpy="0 0 0" xyz="0 0 0"/>
      </collision>      
      <inertial>
        <mass value="0.01" />
        <origin xyz="0 0 0" />
        <inertia ixx="0.001" ixy="0.0" ixz="0.0" iyy="0.001" iyz="0.0" izz="0.001" />
      </inertial>
    </link>
-->
	<joint name="robot_caster_back_joint" type="fixed">
		<parent link="base_link"/>
		<child link="robot_caster_back_link"/>
		<origin xyz="0.05 0 -0.007" rpy="0 0 0"/>
	
	</joint>


	<link name="robot_caster_back_link">
		<inertial>
			<origin xyz="0 0 0"/>
			<mass value="0.01" />
			<inertia ixx="0.001" ixy="0.0" ixz="0.0" iyy="0.001" iyz="0.0" izz="0.001" />
			
		</inertial>

		<visual>
			<origin xyz="0 0 -0.0115" rpy="0 0 0" />
			<geometry>
				<cylinder radius="0.01" length = "0.045"/>
			</geometry>
			<material name ="black" />
		</visual>

		<collision>
			<origin xyz="0 0 -0.0115" rpy="0 0 0" />
			<geometry>
				<cylinder radius="0.01" length = "0.055"/>
			</geometry>
		</collision>
	</link>



	<!--  </xacro:macro> -->
	<joint name="robot_caster_front_joint" type="fixed">
		<parent link="base_link"/>
		<child link="robot_caster_front_link"/>
		<origin xyz="-0.05 0 -0.007" rpy="0 0 0"/>
		
	</joint>


	<link name="robot_caster_front_link">
		<inertial>
			<origin xyz="0 0 0"/>
			<mass value="0.01" />
			<inertia ixx="0.001" ixy="0.0" ixz="0.0" iyy="0.001" iyz="0.0" izz="0.001" />
		</inertial>

		<visual>
			<origin xyz="0 0 -0.0115" rpy="0 0 0" />
			<geometry>
				<cylinder radius="0.01" length = "0.045"/>
			</geometry>
			<material name ="black" />
		</visual>

		<collision>
			<origin xyz="0 0 -0.0115" rpy="0 0 0" />
			<geometry>
				<cylinder radius="0.01" length = "0.045"/>
			</geometry>
		</collision>
	</link>

</robot>